[2025-07-16T04:15:55.170+0000] {taskinstance.py:1159} INFO - Dependencies all met for dep_context=non-requeueable deps ti=<TaskInstance: banking_data_quality_dag.generate_data manual__2025-07-16T04:15:54.040617+00:00 [queued]>
[2025-07-16T04:15:55.179+0000] {taskinstance.py:1159} INFO - Dependencies all met for dep_context=requeueable deps ti=<TaskInstance: banking_data_quality_dag.generate_data manual__2025-07-16T04:15:54.040617+00:00 [queued]>
[2025-07-16T04:15:55.180+0000] {taskinstance.py:1361} INFO - Starting attempt 1 of 2
[2025-07-16T04:15:55.193+0000] {taskinstance.py:1382} INFO - Executing <Task(BashOperator): generate_data> on 2025-07-16 04:15:54.040617+00:00
[2025-07-16T04:15:55.199+0000] {standard_task_runner.py:57} INFO - Started process 200 to run task
[2025-07-16T04:15:55.201+0000] {standard_task_runner.py:84} INFO - Running: ['***', 'tasks', 'run', 'banking_data_quality_dag', 'generate_data', 'manual__2025-07-16T04:15:54.040617+00:00', '--job-id', '2', '--raw', '--subdir', 'DAGS_FOLDER/banking_dq_dag.py', '--cfg-path', '/tmp/tmpl0ybp5_r']
[2025-07-16T04:15:55.203+0000] {standard_task_runner.py:85} INFO - Job 2: Subtask generate_data
[2025-07-16T04:15:55.254+0000] {task_command.py:416} INFO - Running <TaskInstance: banking_data_quality_dag.generate_data manual__2025-07-16T04:15:54.040617+00:00 [running]> on host be9bd688ef95
[2025-07-16T04:15:55.350+0000] {taskinstance.py:1662} INFO - Exporting env vars: AIRFLOW_CTX_DAG_OWNER='***' AIRFLOW_CTX_DAG_ID='banking_data_quality_dag' AIRFLOW_CTX_TASK_ID='generate_data' AIRFLOW_CTX_EXECUTION_DATE='2025-07-16T04:15:54.040617+00:00' AIRFLOW_CTX_TRY_NUMBER='1' AIRFLOW_CTX_DAG_RUN_ID='manual__2025-07-16T04:15:54.040617+00:00'
[2025-07-16T04:15:55.352+0000] {subprocess.py:63} INFO - Tmp dir root location: /tmp
[2025-07-16T04:15:55.353+0000] {subprocess.py:75} INFO - Running command: ['/bin/bash', '-c', 'python /opt/***/jobs/generate_data.py']
[2025-07-16T04:15:55.367+0000] {subprocess.py:86} INFO - Output:
[2025-07-16T04:15:57.019+0000] {subprocess.py:93} INFO - Traceback (most recent call last):
[2025-07-16T04:15:57.020+0000] {subprocess.py:93} INFO -   File "/opt/***/jobs/generate_data.py", line 6, in <module>
[2025-07-16T04:15:57.023+0000] {subprocess.py:93} INFO -     import faker
[2025-07-16T04:15:57.024+0000] {subprocess.py:93} INFO - ModuleNotFoundError: No module named 'faker'
[2025-07-16T04:15:57.193+0000] {subprocess.py:97} INFO - Command exited with return code 1
[2025-07-16T04:15:57.211+0000] {taskinstance.py:1937} ERROR - Task failed with exception
Traceback (most recent call last):
  File "/home/airflow/.local/lib/python3.9/site-packages/airflow/operators/bash.py", line 210, in execute
    raise AirflowException(
airflow.exceptions.AirflowException: Bash command failed. The command returned a non-zero exit code 1.
[2025-07-16T04:15:57.220+0000] {taskinstance.py:1400} INFO - Marking task as UP_FOR_RETRY. dag_id=banking_data_quality_dag, task_id=generate_data, execution_date=20250716T041554, start_date=20250716T041555, end_date=20250716T041557
[2025-07-16T04:15:57.247+0000] {standard_task_runner.py:104} ERROR - Failed to execute job 2 for task generate_data (Bash command failed. The command returned a non-zero exit code 1.; 200)
[2025-07-16T04:15:57.263+0000] {local_task_job_runner.py:228} INFO - Task exited with return code 1
[2025-07-16T04:15:57.305+0000] {taskinstance.py:2778} INFO - 0 downstream tasks scheduled from follow-on schedule check
